No exception
I am inside finally block
Test completed
