There is no exception
I am inside finally block
Test completed
